Workbook

Sheet Presentación

Sheet Inception Ágil
B2: INCEPTION ÁGIL
B4: Para que estamos acá | C4: Desarrollo de una plataforma web para la gestion en tiempo real para un parque infantil tipo playground YUPI SAC
B5: Elevator Pitch
B6: Caja del Producto
B7: Lista del SINOES
B8: Stakeholders
B9: La Solución | C9: Solución Web desarrollado en Java web JSP, HTML5, CSS. Motor de Base de Datos Mysql. Framework Bootstrap, Spring MVC, React/Vite, RIA, otras librerías
B10: Matriz de Riesgos del Proyecto
B11: Alcance del Proyecto | C11: El proyecto se enfoca en la gestion de las actividades diarias de los trabajadores para con el cliente como el registro, cotizacion y agendamiento de eventos asi como tambien el control del tiempo de estadia.
B12: Atributos de Calidad
B13: Costo del Proyecto | C13: S/. 5633.3
B18: COMUNIDAD (STAKEHOLDERS)
E19: Rol | G19: Breve Descripción
B20: 1 . Mauro Aldair Lopez Aiquipa | E20: Gerente General | G20: Lider del negocio que cumple la funcion de monitoreo, control y finanzas
B21: 2. Tamara Carolina Bringas Perez | E21: Gerente Administrativa | G21: Brinda asistencia al Gerente General en las funciones necesarias.
B22: 3. Karla Tupañauqui | E22: Recepcion / Cafetin | G22: Atencion al cliente y gestion de funciones diarias del negocio
B23: 4. Mary Aiquipa | E23: Asistente de Recepcion | G23: Soporte al personal de Recepcion
B24: 5. Andrea Lopez Aiquipa | E24: Diseñadora | G24: Realizar las funciones de decoracion, diseño y publicidad

Sheet Historias de Usuario
B2: HISTORIAS DE USUARIO
B4: HU | C4: Descripción de las Historias de Usuario | D4: EPICAS | F4: PROBLEMA
B5: HU1 | C5: Cómo Recepcionista, quiero registrar la informacion de los cliente para tener acceso correctamente a su informacion. | D5: Gestión de Registro | F5: El negocio Playground Indoor Yupi SAC, cuenta con la herramienta EXCEL para el registro y gestion de clientes por lo cual en la actualidad es necesario la transformacion digital para asi facilidades asi como tambien automatizar actividades de gestion en el negocio ademas cumplir con normas de seguridad de la informacion de datos personales a causa de mantener la satisfaccion del cliente. La sede del negocio se encuentra en el distrito de Miraflores con un espacio amplio de 140m2 con ambientes seguros para la diversion de los niños. En cuanto a la solucion de la necesidades observadas mediante el analisis contextual con la parte interesada de este proyecto se realizará la implementacion de la solucion web para asi modernizar e integrar la norma de transformacion digital para la interoperatibilidad, seguridad y gestion en el negocio para cubrir las necesidades detectadas para otorgar facilidades en la gestion, accesibilidad y disponibilidad asi como tambien la seguridad de su informacion.
B6: HU2 | C6: Cómo Recepcionista, quiero registrar la informacion de los niños asociados a un cliente para controlar correctamente su ingreso al establecimiento.
B7: HU3 | C7: Como recepcionista, quiero consultar la información de los clientes registrados para acceder rápidamente a sus datos cuando sea necesario.
B8: HU4 | C8: Como recepcionista, quiero actualizar la información de clientes y niños para mantener los datos correctos y actualizados.
B9: H05 | C9: Como administrador, quiero visualizar el historial de visitas de cada cliente para conocer la frecuencia de uso del servicio.
B10: HU6 | C10: Como recepcionista, quiero registrar la hora de ingreso de los niños para iniciar el control del tiempo de permanencia. | D10: Gestion del Tiempo de Estadia
B11: HU7 | C11: Como recepcionista, quiero registrar la hora de salida de los niños para finalizar el control de su permanencia. | F11: PRODUCTO (SOFTWARE)
F12: Elaborar una Solución Web para la gestion en tiempo real del playground indoor Yupi SAC. Puede utilizar framework como: Spring Boot, Bootstrap, React/Vite y diferentes dependencias para el desarrollo del aplicativo. Lenguaje de Programación Java Web JSP, HTML5, CSS; Motor de Base de Datos Mysql, para el diseño del modelo de base de datos Bizagui Modeler, Mysqlworkbench.El patrón de la arquitectura de software es Arquitectua en Capas o Desarrollo Front End - Desarrollo Backend.
B13: HU8 | C13: Como recepcionista, quiero que el sistema calcule automáticamente el tiempo de permanencia para evitar errores de cálculo.
B17: HU9 | C17: Como recepcionista, quiero visualizar en tiempo real el tiempo restante de cada sesión para informar oportunamente a los clientes.
H20: ARQUITECTURA DE DISEÑO DE LA SOLUCIÓN WEB
B21: HU10 | C21: Como recepcionista, quiero recibir alertas cuando el tiempo contratado esté próximo a finalizar para avisar al cliente con anticipación.
B25: HU11 | C25: Como administrador, quiero visualizar la cantidad de clientes del Playground para controlar la cantidad de personas en el playground.
B28: HU12 | C28: Como recepcionista, quiero registrar reservas para eventos y cumpleaños para asi organizar la programación del establecimiento. | D28: Gestion de Eventos y Agenda
B31: HU13 | C31: Como recepcionista, quiero verificar la disponibilidad de fechas y horarios para evitar conflictos entre reservas.
B35: HU14 | C35: Como recepcionista, quiero modificar o cancelar reservas para atender los cambios solicitados por los clientes.
B38: HU15 | C38: Como recepcionista, quiero consultar un calendario de reservas para visualizar los eventos programados.
B41: HU16 | C41: Como recepcionista, quiero generar cotizaciones para eventos infantiles para ofrecer propuestas según el paquete establecido.
B44: HU17 | C44: Como recepcionista, quiero que el sistema calcule automáticamente el costo según el paquete seleccionado para agilizar la elaboración de cotizaciones.
B47: HU18 | C47: Como recepcionista, quiero agregar servicios adicionales a una cotización para personalizar los eventos según las necesidades del cliente.
B50: HU19 | C50: Como cliente, quiero conocer el monto total de la cotización para decidir si acepto el servicio ofrecido.
B53: HU20 | C53: Como recepcionista, quiero convertir una cotización aprobada en una reserva para evitar registrar nuevamente la información.
B56: HU21 | C56: Como cajera, quiero registrar el dinero al ingresar y el monto de salida para tener en cuenta el monto de excedente. | D56: Gestion de Caja
B59: HU22 | C59: Como cajera, quiero registrar los pagos realizados por los clientes para mantener actualizado el estado de las cuentas. | K59: EPICAS
I61: HU | K61: HU | M61: HU | O61: HU | Q61: HU | S61: TAREAS
B62: HU23 | C62: Como cajero, quiero registrar pagos parciales y pagos completos de los eventos para controlar correctamente las obligaciones pendientes.
B65: HU24 | C65: Como administrador, quiero generar el cierre diario de caja para controlar los ingresos obtenidos durante la jornada.
B68: HU25 | C68: Como usuario del sistema, quiero iniciar sesión con mis credenciales para acceder únicamente a las funciones autorizadas. | D68: Gestionar Seguridad
S70: SUB TAREAS
B71: HU26 | C71: Como administrador, quiero administrar los usuarios del sistema para controlar quiern tiene acceso a la aplicación.
B74: HU27 | C74: Como administrador, quiero asignar roles y permisos a los usuarios para restringir el acceso según sus responsabilidades.

Sheet Product Backlog
C2: PRODUCT BACKLOG NO PRIORIZADO
C4: PB_ID | D4: DESCRIPCIÓN
C5: PB01 | D5: Gestion de Clientes
C6: PB02 | D6: Gestion de niños asociados a los Clientes
C7: PB03 | D7: Consulta de Clientes/niños
C8: PB04 | D8: Actualizacion de informacion de Clientes/niños
C9: PB05 | D9: Historial de visitas
C10: PB06 | D10: Registro de ingreso de los Clientes/niños
C11: PB07 | D11: Registro de salida de los Clientes/niños
C12: PB08 | D12: Control de tiempo de permanencia
C13: PB09 | D13: Visualizar tiempo restante de permanencia
C14: PB10 | D14: Generar alertas acerca del tiempo de permanencia
C15: PB11 | D15: Observar la cantidad de clientes en tiempo real
... C29: PB25 | D29: Permisos y Roles
C30: PB26

Sheet Product Backlog Priorizado
C1: PRODUCT BACKLOG PRIORIZADO CON LA TÉCNICA DE MOSCOW
C4: PB_ID | D4: DESCRIPCIÓN | E4: PRIORIZADO
C5: PB01 | D5: Gestion de Clientes | E5: M
C6: PB02 | D6: Gestion de niños asociados a los Clientes | E6: M
C7: PB03 | D7: Consulta de Clientes/niños | E7: M
C8: PB04 | D8: Actualizacion de informacion de Clientes/niños | E8: S
C9: PB05 | D9: Historial de visitas | E9: C
C10: PB06 | D10: Registro de ingreso de los Clientes/niños | E10: M
C11: PB07 | D11: Registro de salida de los Clientes/niños | E11: M
C12: PB08 | D12: Control de tiempo de permanencia | E12: M | Q12: M | S12: HIGHEST
C13: PB09 | D13: Visualizar tiempo restante de permanencia | E13: S | Q13: 1
C14: PB10 | D14: Generar alertas acerca del tiempo de permanencia | E14: S
C15: PB11 | D15: Observar la cantidad de clientes en tiempo real | E15: C
C16: PB12 | D16: Registro de reservas de eventos y cumpleaños | E16: M | Q16: S | S16: HIGHT
C17: PB13 | D17: Consultar la disponibilidad de eventos | E17: M | Q17: 2
C18: PB14 | D18: Modificar o cancelar la reserva | E18: S
C19: PB15 | D19: Consultar calendario de reserva | E19: C
C20: PB16 | D20: Generar cotizacion por paquete de evento | E20: M
C21: PB17 | D21: Generar el costo por evento | E21: M | Q21: C | S21: MEDIUM
C22: PB18 | D22: Agregar servicios adicionales al evento | E22: S | Q22: 3
C23: PB19 | D23: Conversion de cotizacion a reserva | E23: M
C24: PB20 | D24: Registro de apertura de caja | E24: M
C25: PB21 | D25: Gestion de pagos | E25: M | Q25: W | S25: LOW
C26: PB22 | D26: Regsitro de pagos por evento parcial/completo | E26: S | Q26: 4
C27: PB23 | D27: Registro de cierre de caja | E27: M
C28: PB24 | D28: Gestion de usuarios | E28: M
C29: PB25 | D29: Permisos y Roles | E29: M
C30: PB26 | D30: Control de acceso de usuarios | E30: M

Sheet Product Backlog  Prior_Estimad
G1: Criterio de estimación
B2: PRODUCT BACKLOG PRIORIZADO Y ESTIMADO | G2: 10 – 30 puntos | H2: Funcionalidad sencilla, pocas reglas de negocio y baja complejidad. | I2: 40 – 60 puntos | J2: Complejidad media, requiere validaciones, varias pantallas o interacción con diferentes componentes. | K2: 70 – 80 puntos | L2: Funcionalidad compleja con múltiples procesos, integración entre módulos y reglas de negocio importantes. | M2: 90 – 100 puntos | N2: Funcionalidad crítica de alta complejidad, con numerosas dependencias, integración con otros servicios o algoritmos complejos
E3: 10 - 100
B4: PB_ID | C4: DESCRIPCION | D4: PRIORIZADO | E4: ESTIMADO
B5: PB01 | C5: Gestion de Clientes | D5: M | E5: 80
B6: PB02 | C6: Gestion de niños asociados a los Clientes | D6: M | E6: 60 | F6: PIVOTE
B7: PB03 | C7: Consulta de Clientes/niños | D7: M | E7: 30
B8: PB04 | C8: Actualizacion de informacion de Clientes/niños | D8: S | E8: 40
B9: PB05 | C9: Historial de visitas | D9: C | E9: 30
B10: PB06 | C10: Registro de ingreso de los Clientes/niños | D10: M | E10: 50
B11: PB07 | C11: Registro de salida de los Clientes/niños | D11: M | E11: 50
B12: PB08 | C12: Control de tiempo de permanencia | D12: M | E12: 70
B13: PB09 | C13: Visualizar tiempo restante de permanencia | D13: S | E13: 40
B14: PB10 | C14: Generar alertas acerca del tiempo de permanencia | D14: S | E14: 60
B15: PB11 | C15: Observar la cantidad de clientes en tiempo real | D15: C | E15: 40
B16: PB12 | C16: Registro de reservas de eventos y cumpleaños | D16: M | E16: 80
B17: PB13 | C17: Consultar la disponibilidad de eventos | D17: M | E17: 50
B18: PB14 | C18: Modificar o cancelar la reserva | D18: S | E18: 40
... B30: PB26 | C30: Control de acceso de usuarios | D30: M | E30: 50
C34: MVP (Minimun Viable Product) =

Sheet Longitud del Sprint
C2: DETERMINACIÓN DE LA LONGITUD DEL SPRINT
B4: LONGITUD DEL SPRINT | D4: Nombre del Negocio | E4: YUPI SAC | F4: Fecha:04/07/2026
D5: Participantes | E5: 1. Makino Pérez, Eder Kenzo
B9: SPRINT | C9: Nro. | D9: TEMAS | E9: Contenido | F9: Fechas
B10: Sprint 1 | C10: 1 | D10: Semana 09 | E10: PB01, PB02, PB24, PB25, PB26 | F10: 46216 | G10: MVP
C11: 2 | D11: Semana 10 | E11: PB03, PB04, PB05, PB06, PB07 | I11: SPRINT BACKLOG
B12: Sprint 2 | C12: 5 | D12: Semana 11 | E12: PB08, PB09, PB10, PB11 | F12: 46230
C13: 6 | D13: Semana 12 | E13: PB12, PB13, PB14, PB15 | H13: SPRINT 2
B14: Sprint 3 | C14: 7 | D14: Semana 13 | E14: PB16, PB17, PB18, PB19 | F14: 46244
C15: 8 | D15: Semana 14 | E15: PB20, PB21, PB22, PB23 | H15: SPRINT 3
E20: SPRINT 1: 2 SEMANAS | F20: SCRUM MASTER
E21: SPRINT 2: 2 SEMANAS | F21: PRODUCT OWNER
E22: SPRINT 3: 2 SEMANAS | F22: DEVELOPERS
C24: 1.0 Procut Backlog
C26: 2.0 Sprint Backlog
C28: 3.0 Incremento Producto

Sheet MVP - SPRINTS
C2: DETERMINACIÓN DEL MVP Y LOS SPRINT
C4: PB_ID | D4: DESCRIPCIÓN | E4: MOSCOW | F4: ESTIMADO | H4: =SUM(F5:F14) -> 520
C5: PB01 | D5: Gestion de Clientes | E5: ='Product Backlog Prior_Estimad'!D5 -> M | F5: ='Product Backlog Prior_Estimad'!E5 -> 80
C6: PB02 | D6: Gestion de niños asociados a los Clientes | E6: ='Product Backlog Prior_Estimad'!D6 -> M | F6: ='Product Backlog Prior_Estimad'!E6 -> 60 | H6: RELEASE 1
C7: PB03 | D7: Consulta de Clientes/niños | E7: ='Product Backlog Prior_Estimad'!D7 -> M | F7: ='Product Backlog Prior_Estimad'!E7 -> 30
C8: PB04 | D8: Actualizacion de informacion de Clientes/niños | E8: ='Product Backlog Prior_Estimad'!D8 -> S | F8: ='Product Backlog Prior_Estimad'!E8 -> 40 | H8: SPRINT 1
C9: PB05 | D9: Historial de visitas | E9: ='Product Backlog Prior_Estimad'!D9 -> C | F9: ='Product Backlog Prior_Estimad'!E9 -> 30
C10: PB06 | D10: Registro de ingreso de los Clientes/niños | E10: ='Product Backlog Prior_Estimad'!D10 -> M | F10: ='Product Backlog Prior_Estimad'!E10 -> 50 | H10: MVP
C11: PB07 | D11: Registro de salida de los Clientes/niños | E11: ='Product Backlog Prior_Estimad'!D11 -> M | F11: ='Product Backlog Prior_Estimad'!E11 -> 50
C12: ='Product Backlog'!C28 -> PB24 | D12: Gestion del Acceso de los Usuarios del Sistema | E12: ='Product Backlog Prior_Estimad'!D28 -> M | F12: ='Product Backlog Prior_Estimad'!E28 -> 70 | H12: Semana 10 | I12: 46216
C13: ='Product Backlog'!C29 -> PB25 | D13: ='Product Backlog'!D29 -> Permisos y Roles | E13: ='Product Backlog Prior_Estimad'!D29 -> M | F13: ='Product Backlog Prior_Estimad'!E29 -> 60
C14: ='Product Backlog'!C30 -> PB26 | D14: Control de acceso de usuarios | E14: ='Product Backlog Prior_Estimad'!D30 -> M | F14: ='Product Backlog Prior_Estimad'!E30 -> 50
C15: ='Product Backlog Prior_Estimad'!B12 -> PB08 | D15: ='Product Backlog Prior_Estimad'!C12 -> Control de tiempo de permanencia | E15: ='Product Backlog Prior_Estimad'!D12 -> M | F15: ='Product Backlog Prior_Estimad'!E12 -> 70
C16: ='Product Backlog Prior_Estimad'!B13 -> PB09 | D16: ='Product Backlog Prior_Estimad'!C13 -> Visualizar tiempo restante de permanencia | E16: ='Product Backlog Prior_Estimad'!D13 -> S | F16: ='Product Backlog Prior_Estimad'!E13 -> 40
C17: ='Product Backlog Prior_Estimad'!B14 -> PB10 | D17: ='Product Backlog Prior_Estimad'!C14 -> Generar alertas acerca del tiempo de permanencia | E17: ='Product Backlog Prior_Estimad'!D14 -> S | F17: ='Product Backlog Prior_Estimad'!E14 -> 60 | H17: SPRINT 2 | I17: 46230
C18: ='Product Backlog Prior_Estimad'!B15 -> PB11 | D18: ='Product Backlog Prior_Estimad'!C15 -> Observar la cantidad de clientes en tiempo real | E18: ='Product Backlog Prior_Estimad'!D15 -> C | F18: ='Product Backlog Prior_Estimad'!E15 -> 40 | H18: Semana 12
C19: ='Product Backlog Prior_Estimad'!B16 -> PB12 | D19: ='Product Backlog Prior_Estimad'!C16 -> Registro de reservas de eventos y cumpleaños | E19: ='Product Backlog Prior_Estimad'!D16 -> M | F19: ='Product Backlog Prior_Estimad'!E16 -> 80
C20: ='Product Backlog Prior_Estimad'!B17 -> PB13 | D20: ='Product Backlog Prior_Estimad'!C17 -> Consultar la disponibilidad de eventos | E20: ='Product Backlog Prior_Estimad'!D17 -> M | F20: ='Product Backlog Prior_Estimad'!E17 -> 50
C21: ='Product Backlog Prior_Estimad'!B18 -> PB14 | D21: ='Product Backlog Prior_Estimad'!C18 -> Modificar o cancelar la reserva | E21: ='Product Backlog Prior_Estimad'!D18 -> S | F21: ='Product Backlog Prior_Estimad'!E18 -> 40
C22: ='Product Backlog Prior_Estimad'!B19 -> PB15 | D22: ='Product Backlog Prior_Estimad'!C19 -> Consultar calendario de reserva | E22: ='Product Backlog Prior_Estimad'!D19 -> C | F22: ='Product Backlog Prior_Estimad'!E19 -> 50
C23: ='Product Backlog Prior_Estimad'!B20 -> PB16 | D23: ='Product Backlog Prior_Estimad'!C20 -> Generar cotizacion por paquete de evento | E23: ='Product Backlog Prior_Estimad'!D20 -> M | F23: ='Product Backlog Prior_Estimad'!E20 -> 70
C24: ='Product Backlog Prior_Estimad'!B21 -> PB17 | D24: ='Product Backlog Prior_Estimad'!C21 -> Generar el costo por evento | E24: ='Product Backlog Prior_Estimad'!D21 -> M | F24: ='Product Backlog Prior_Estimad'!E21 -> 60
C25: ='Product Backlog Prior_Estimad'!B22 -> PB18 | D25: ='Product Backlog Prior_Estimad'!C22 -> Agregar servicios adicionales al evento | E25: ='Product Backlog Prior_Estimad'!D22 -> S | F25: ='Product Backlog Prior_Estimad'!E22 -> 40
C26: ='Product Backlog Prior_Estimad'!B23 -> PB19 | D26: ='Product Backlog Prior_Estimad'!C23 -> Conversion de cotizacion a reserva | E26: ='Product Backlog Prior_Estimad'!D23 -> M | F26: ='Product Backlog Prior_Estimad'!E23 -> 50
C27: ='Product Backlog Prior_Estimad'!B24 -> PB20 | D27: ='Product Backlog Prior_Estimad'!C24 -> Registro de apertura de caja | E27: ='Product Backlog Prior_Estimad'!D24 -> M | F27: ='Product Backlog Prior_Estimad'!E24 -> 30 | H27: SPRINT 3 | I27: 46244
C28: ='Product Backlog Prior_Estimad'!B25 -> PB21 | D28: ='Product Backlog Prior_Estimad'!C25 -> Gestion de pagos | E28: ='Product Backlog Prior_Estimad'!D25 -> M | F28: ='Product Backlog Prior_Estimad'!E25 -> 80
C29: ='Product Backlog Prior_Estimad'!B26 -> PB22 | D29: ='Product Backlog Prior_Estimad'!C26 -> Regsitro de pagos por evento parcial/completo | E29: ='Product Backlog Prior_Estimad'!D26 -> S | F29: ='Product Backlog Prior_Estimad'!E26 -> 50
C30: ='Product Backlog Prior_Estimad'!B27 -> PB23 | D30: ='Product Backlog Prior_Estimad'!C27 -> Registro de cierre de caja | E30: ='Product Backlog Prior_Estimad'!D27 -> M | F30: ='Product Backlog Prior_Estimad'!E27 -> 40 | H30: Semana 14

Sheet Criterios de Aceptación
B2: CRITERIOS DE ACEPTACIÓN DE LAS HISTORIAS DE USUARIO
B4: Historia de Usuario: HU01 | C4: Título: | D4: Gestion de Clientes
B5: Developer :Eder Makino | C5: Usuario: Recepcionista | G5: Sprint: Sprint 1, MVP
B6: Descripción de la HU01 | C6: Cómo | D6: Recepcionista
C7: Quiero | D7: Registrar la informacion de los clientes del Playground
C8: Para | D8: Mantener una base de datos actualizada que facilite el control de los servicios ofrecidos y la atencion a los clientes
B9: Criterios de Aceptación | C9: CRITERIOS DE ACEPTACION 1.0 La solucion web debe permitir registrar un nuevo cliente mediante un formulario con una interfaz grafica amigable e intuitiva 2.0 El sistema debe solicitar como minimo los siguiente datos del cliente: DNI, Nombres, Apellidos, Fecha de Nacimiento, Telefono, Correo Electronico, Direccion 3.0 Todos los campos obligatorios deberan ser validados antes de guardar la informacion 4.0 El sistema no deberá permitir registrar clientes con un DNI ya existente 5.0 El sistema debera validar que el formato del correo electronico sea correcto 6.0 El sistema debera validar que el numero telefonico contenga unicamente caracteres numericos y la longitud permitida. 7.0 Al registrar correctamente un cliente, el sistema debera mostrar un mensaje de confirmacion indicando que el registro fue exitoso. 8.0 En caso de producirse un error durante el registro, el sistema debera mostrar un mensaje indicando la causa del problema. 9.0 El sistema deberá almacenar la informacion del cliente en la base de datos y actualizar automaticamente el listado de clientes registrados. 10.0 El sistema deberá registrar la fecha y hora en que se realizó el registro del cliente. SUB TAREAS 1.0 Analizar la Historia de Usuario HU01 y sus criterios de aceptacion 2.0 Diseñar el formulario de Registro de Clientes con una interfaz amigable utilizando HTML5, CSS3 y Bootstrap. 3.0 Diseñar los campos del formulario de registro de clientes 4.0 Crear la entidad Cliente con sus atributos y tipos de datos correspondientes. 5.0 Diseñar la tabla Clientes en la base de datos MySQL 6.0 Desarrollar el Front-End del formulario utilizando HTML5, CSS3, JavaScript y Bootstrap. 7.0 Implementar la logica de negocio en el BackEnd para registrar clientes y validar la informacion ingresada. 8.0 Implementar las validaciones de datos y evitar registros duplicados por DNI. 9.0 Realizar pruebas de integracion entre el Front-End, el Back-End y la Base de Datos 10.0 Mostrar el mensaje de confirmacion y actualizar automaticamente el listado de clientes registrados. | I9: Prioridad Técnica MOSCOW | J9: M
I15: Puntos Estimados | J15: 80
B23: Historia de Usuario: HU02 | C23: Título: | D23: Gestion de niños asociados a los Clientes
B24: Developer: Eder Makino | C24: Usuario: Recepcionista | G24: Sprint: Sprint 1, MVP
B25: Descripción de la HU02 | C25: Cómo | D25: Recepcionista
C26: Quiero | D26: Registrar la informacion de los niños asociados a un cliente
C27: Para | D27: Mantener el control de los menores que ingresan al Playground y relacionarlos con su responsable
B28: Criterios de Aceptación | C28: 1.0 La solucion web debe permitir uno o mas niños asociados a un cliente prviamente registrado. 2.0 El sistema debera permitir seleccionar al cliente responsale mediante la busqueda por DNI, nombre o codigo de cliente 3.0 El formulario de registro deberá solicitar como minimo la siguiente informacion del niño: Nombres, Apellidos, Fecha de Nacimiento, Edad, Sexo, Observaciones(opcional) 4.0 Todos los campos obligatorios deberán ser validados antes de registrar la informacion. 5.0 El sistema deberá calcular automaticamente la edad del niño a partir de la fecha de nacimiento o validar que la edad ingresada sea consistente. 6.0 El sistema no deberá permitir registrar al mismo niño más de una vez para un mismo cliente cuando exista coincidencia de nombres y fecha de nacimiento. 7.0 El sistema deberá verificar que el cliente responsable exista antes de permitir el registro del niño. 8.0 Al finalizar el registro correctamente, el sistema deberá mostrar un mensaje indicando que el niño fue registrado satisfactoriamente. 9.0 Si ocurre algun error durante el registro, el sistema deberá mostrar un mensaje indicando la causa del problema. 10.0 El sistema deberá almacenar la información del niño en la base de datos y mantener la relación con el cliente responsable. 11.0 El sistema deberá permitir registrar varios niños para un mismo cliente. 12.0 El sistema deberá actualizar automáticamente el listado de niños asociados al cliente una vez realizado el registro. SUB TAREAS 1.0 Analizar la Historia de Usuario HU02 considerando los criterios de aceptacion. 2.0 Diseñar el formulario de registro de niños con una interfaz grafica amigable utilizando HTML5, CSS3 y Bootstrap. 3.0 Diseñar los campos necesarios para registrar la informacion del niño. 4.0 Crear la entidad Niño con sus respectivos atributos y su relacion con la entidad Cliente. 5.0 Diseñar la tabla Niños y la relacion con la tabla Clientes en la base de datos MySQL 6.0 Implementar el formulario en el Front-End utilizando HTML5, CSS3, JavaScript y Bootstrap. 7.0 Desarrollar la logica del Back-End para registrar niños asociados a un cliente. 8.0 Implementar las validaciones de datos y evitar registros duplicados. 9.0 Realizar pruebas de integracion entre el Front-End, el Back-End y la base de datos. 10.0 Verificar que el listado de niños asociados al cliente se actualice correctamente despues del registro. | I28: Prioridad Técnica MOSCOW | J28: M
I34: Puntos Estimados | J34: 60
B42: Historia de Usuario: HU03 | C42: Título: | D42: Consulta de Clientes y Niños
B43: Developer: Eder Kenzo Makino Perez | C43: Usuario: Recepcionista | G43: Sprint: Sprint 1 - MVP
B44: Descripción de la HU03 | C44: Cómo | D44: Recepcionista
C45: Quiero | D45: Consultar la informacion de los Clientes y de los niños asociados mediante una busqueda rápida
C46: Para | D46: Acceder de forma inmediata a la informacion necesaria durante la atencion en el Playground
B47: Criterios de Aceptación | C47: CRITERIOS DE ACEPTACION 1.0 La solución web deberá permitir buscar clientes registrados mediante DNI, nombre, apellido o código de cliente. 2.0 El sistema deberá mostrar únicamente los clientes que coincidan con el criterio de búsqueda ingresado. 3.0 Al seleccionar un cliente, el sistema deberá mostrar automáticamente toda la información registrada del cliente. 4.0 El sistema deberá mostrar el listado de todos los niños asociados al cliente seleccionado. 5.0 El sistema deberá mostrar como mínimo la siguiente información de cada niño:Nombres, Apellidos, Edad, Sexo,Fecha de nacimiento 6.0 El sistema deberá permitir realizar nuevas búsquedas sin necesidad de recargar la página. 7.0 Si no existen coincidencias con el criterio de búsqueda, el sistema deberá mostrar un mensaje indicando que no se encontraron registros. 8.0 El sistema deberá mostrar la información consultada en una tabla organizada y de fácil lectura. 9.0 El sistema deberá permitir visualizar la cantidad de niños asociados al cliente seleccionado. 10.0 El sistema deberá ordenar los resultados de búsqueda por nombre del cliente de forma ascendente. 11.0 El sistema deberá mostrar el estado del cliente (Activo/Inactivo) si dicha información existe en el sistema. 12.0 La consulta deberá realizarse sin modificar la información almacenada en la base de datos. 13.0 El sistema deberá responder a la búsqueda en un tiempo adecuado para garantizar una atención rápida al cliente. SUB TAREAS 1.0 Analizar la Historia de Usuario HU03 considerando los criterios de aceptación. 2.0 Diseñar la interfaz de consulta de clientes utilizando HTML5, CSS3 y Bootstrap. 3.0 Diseñar el componente de búsqueda por DNI, nombre y código de cliente. 4.0 Implementar la tabla para visualizar la información de los clientes encontrados. 5.0 Implementar la tabla para visualizar los niños asociados al cliente seleccionado. 6.0 Desarrollar la lógica del Back-End para consultar clientes y sus niños asociados. 7.0 Implementar consultas SQL optimizadas para obtener la información de clientes y niños relacionados. 8.0 Implementar filtros de búsqueda por DNI, nombre y código de cliente. 9.0 Implementar mensajes cuando no existan resultados de búsqueda. 10.0 Realizar pruebas de integración entre Front-End, Back-End y Base de Datos verificando la correcta visualización de clientes y niños asociados. | I47: Prioridad Técnica MOSCOW | J47: M
I53: Puntos Estimados | J53: 30
B61: Historia de Usuario: HU04 | C61: Título: | D61: Actualizacion de informacion de Clientes/niños
B62: Developer: Eder Kenzo Makino Perez | C62: Usuario: Recepcionista | G62: Sprint: Sprint 1 - MVP
B63: Descripción de la HU04 | C63: Cómo | D63: Recepcionista
C64: Quiero | D64: Gestionar la informacion de los clientes y de los niños asociados
C65: Para | D65: Mantener actualizados los datos pernosales y garantizar una atencion eficiente en el Playground
B66: Criterios de Aceptación | C66: 1.0 La solución web deberá permitir localizar un cliente registrado mediante la búsqueda por DNI, nombre o código de cliente. 2.0 El sistema deberá mostrar la información completa del cliente seleccionado junto con los niños asociados. 3.0 El sistema deberá permitir modificar la información del cliente cuando sea necesario. 4.0 El sistema deberá permitir modificar la información de cualquiera de los niños asociados al cliente. 5.0 Todos los campos obligatorios deberán ser validados antes de guardar los cambios realizados. 6.0 El sistema deberá validar que no existan registros duplicados de clientes o niños al momento de actualizar la información. 7.0 Si se modifica la fecha de nacimiento del niño, el sistema deberá recalcular automáticamente su edad. 8.0 El sistema deberá conservar la relación existente entre el cliente y sus niños asociados después de realizar la actualización. 9.0 El sistema deberá registrar únicamente los cambios realizados sin afectar la información de otros clientes. 10.0 Al guardar correctamente los cambios, el sistema deberá mostrar un mensaje indicando que la información fue actualizada satisfactoriamente. 11.0 Si ocurre algún error durante la actualización, el sistema deberá mostrar un mensaje indicando la causa del problema. 12.0 El sistema deberá actualizar automáticamente la información mostrada en pantalla una vez finalizada la actualización. 13.0 El sistema deberá almacenar los cambios realizados en la base de datos manteniendo la integridad de la información. SUB TAREAS 1.0 Analizar la Historia de Usuario HU04 considerando los criterios de aceptación. 2.0 Diseñar la interfaz para la gestión de clientes y niños utilizando HTML5, CSS3 y Bootstrap. 3.0 Implementar la búsqueda del cliente mediante DNI, nombre o código. 4.0 Implementar la carga automática de la información del cliente y de los niños asociados. 5.0 Desarrollar el formulario de edición de datos del cliente. 6.0 Desarrollar el formulario de edición de datos del niño. 7.0 Implementar las validaciones de los campos obligatorios y reglas de negocio. 8.0 Desarrollar la lógica del Back-End para actualizar la información de clientes y niños. 9.0 Implementar las consultas SQL para actualizar los registros en la base de datos. 10.0 Verificar la integridad de la relación entre Cliente y Niño después de la actualización. 11.0 Implementar mensajes de confirmación y manejo de errores. 12.0 Realizar pruebas de integración entre el Front-End, el Back-End y la base de datos para validar el correcto funcionamiento de la gestión de información. | I66: Prioridad Técnica MOSCOW | J66: S
I72: Puntos Estimados | J72: 40
B80: Historia de Usuario: HU05 | C80: Título: | D80: Historial de visitas
B81: Developer: Eder Kenzo Makino Perez | C81: Usuario: Administrador | G81: Sprint: Sprint 1, MVP
B82: Descripción de la HU05 | C82: Cómo | D82: Administrador
C83: Quiero | D83: Visualizar el hbistorial de visitas de los clientes y de los niños asociados
C84: Para | D84: Conocer la frecuencia de asistencia al Playground y disponer de informacion para la toma de decisiones y la atencion al cliente
B85: Criterios de Aceptación | C85: 1.0 La solución web deberá permitir buscar el historial de visitas de un cliente mediante DNI, nombre o código de cliente. 2.0 El sistema deberá mostrar la información general del cliente seleccionado. 3.0 El sistema deberá mostrar el listado de todos los niños asociados al cliente seleccionado. 4.0 El sistema deberá mostrar el historial de visitas registradas de cada niño asociado. 5.0 Cada registro del historial deberá mostrar como mínimo la siguiente información:Fecha de la visita, Hora de ingreso, Hora de salida, Tiempo de permanencia, Estado de la visita (Finalizada o En curso). 6.0 El sistema deberá ordenar el historial mostrando primero las visitas más recientes. 7.0 El sistema deberá permitir consultar el historial completo sin modificar la información almacenada. 8.0 El sistema deberá permitir filtrar las visitas por rango de fechas. 9.0 El sistema deberá mostrar la cantidad total de visitas realizadas por el cliente. 10.0 El sistema deberá mostrar el tiempo total acumulado de permanencia de los niños registrados cuando la información esté disponible. 11.0 Si el cliente no registra visitas anteriores, el sistema deberá mostrar un mensaje indicando que no existe historial registrado. 12.0 El sistema deberá recuperar la información directamente desde la base de datos garantizando la integridad de los registros. 13.0 La consulta deberá ejecutarse en un tiempo adecuado para garantizar una atención eficiente. SUB TAREAS 1.0 Analizar la Historia de Usuario HU05 considerando los criterios de aceptación. 2.0 Diseñar la interfaz de consulta del historial de visitas utilizando HTML5, CSS3 y Bootstrap. 3.0 Diseñar los filtros de búsqueda por DNI, nombre, código de cliente y rango de fechas. 4.0 Implementar la tabla para visualizar el historial de visitas. 5.0 Implementar la consulta que recupere las visitas registradas de los clientes y niños asociados. 6.0 Desarrollar la lógica del Back-End para consultar el historial de visitas. 7.0 Implementar consultas SQL para recuperar la información desde la base de datos. 8.0 Implementar el cálculo del número total de visitas y del tiempo acumulado de permanencia. 9.0 Implementar mensajes cuando el cliente no registre visitas. 10.0 Realizar pruebas de integración entre el Front-End, el Back-End y la base de datos verificando la correcta visualización del historial. | I85: Prioridad Técnica MOSCOW | J85: C
I91: Puntos Estimados | J91: 30
B99: Historia de Usuario: HU06 | C99: Título: | D99: Registro de Ingreso de Clientes y Niños
B100: Developer: Eder Kenzo Makino Perez | C100: Usuario: Recepcionista | G100: Sprint: Sprint 1, MVP
B101: Descripción de la HU06 | C101: Cómo | D101: Recepcionista
C102: Quiero | D102: Registrar el ingreso de los niños asociados a uin cliente
...

Sheet WBS
B2: WORK BREAKDOWN STRUCTURE (WBS) SOLUCIÓN WEB
B4: Que Como | C4: ANALISIS 1 | D4: DISEÑO 2 | E4: PROGRAMACION 3 | F4: PRUEBAS 4
B5: PB01 | C5: 1.PB01 | D5: 2.PB01 | E5: 3.PB01 | F5: 4.PB01
B6: PB02 | C6: 1.PB02 | D6: 2.PB02 | E6: 3.PB02 | F6: 4.PB02
B7: PB03 | C7: 1.PB03 | D7: 2.PB03 | E7: 3.PB03 | F7: 4.PB03
B8: PB04 | C8: 1.PB04 | D8: 2.PB04 | E8: 3.PB04 | F8: 4.PB04
B9: PB05 | C9: 1.PB05 | D9: 2.PB05 | E9: 3.PB05 | F9: 4.PB05
B10: PB06 | C10: 1.PB06 | D10: 2.PB06 | E10: 3.PB06 | F10: 4.PB06
B11: PB07 | C11: 1.PB07 | D11: 2.PB07 | E11: 3.PB07 | F11: 4.PB07
B12: PB08 | C12: 1.PB08 | D12: 2.PB08 | E12: 3.PB08 | F12: 4.PB08
B13: PB09 | C13: 1.PB09 | D13: 2.PB09 | E13: 3.PB09 | F13: 4.PB09
B14: PB10 | C14: 1.PB10 | D14: 2.PB10 | E14: 3.PB10 | F14: 4.PB10
B15: PB11 | C15: 1.PB11 | D15: 2.PB11 | E15: 3.PB11 | F15: 4.PB11
... B30: PB26 | C30: 1.PB26 | D30: 2.PB26 | E30: 3.PB26 | F30: 4.PB26

Sheet Sprint Planning
A2: SPRINT PLANNING SOLUCIÓN WEB
B4: SPRINT 1 | C4: SPRINT 2 | D4: SPRINT 3
B5: PB01 | C5: PB08 | D5: PB16
B6: PB02 | C6: PB09 | D6: PB17
B7: PB03 | C7: PB10 | D7: PB18
B8: PB04 | C8: PB11 | D8: PB19
B9: PB05 | C9: PB12 | D9: PB20
B10: PB06 | C10: PB13 | D10: PB21
B11: PB07 | C11: PB14 | D11: PB22
B12: PB24 | C12: PB15 | D12: PB23
B13: PB25
B14: PB26

Sheet 2.0 Evento Daily Scrum
B2: EVENTOS SCRUM: SPRINT 1 | D2: Nombre del Negocio | E2: Yupi SAC | F2: Fecha:04/07/2026
D3: Participantes | E3: 1 Eder Kenzo Makino Perez
B7: 2.0 EVENTO DAILY SCRUM
B8: SCRUM TEAM | C8: Meta | D8: ¿ Que hiciste ayer? | E8: ¿ Qué vas a hacer hoy? | F8: ¿ Algún impedimento?
B9: Eder Makino | C9: Primera entrega funcionando en un plazo de 2 semanas (4/07-13/07). De la Solución Web para un Sistema de gestion en Tiempo Real del negocio YUPI SAC PB01, PB02, PB03, PB04, PB05, PB06, PB07, PB24, PB25, PB26 | D9: Modelo de base de datos | E9: Registro de Usuarios | F9: Problemas de conexión a base de datos
D14: Interfaz Login | E14: Interfaz Menu Principal | F14: Problemas de responsividad
D19: Interfaz Registro de Clientes/Niños | E19: BackEnd de los primeras tablas | F19: Errores de Código
D24: Continuacion del BackEnd | E24: Conexión BackEnd-FrontEnd | F24: Ningún error

Sheet 2.1 Evento Daily Scrum
B2: EVENTOS SCRUM: SPRINT 1 | D2: Nombre del Negocio | E2: Karcher Perú SAC | F2: Fecha:01/07/2022
D3: Participantes | E3: 1 Yman Gonzales
E4: 2 Rodriguez Quispe
E5: 3 Cachay Santa Cruz
B7: 2.0 EVENTO DAILY SCRUM
B8: SCRUM TEAM | C8: Meta | D8: ¿ Que hiciste ayer? | E8: ¿ Qué vas a hacer hoy? | F8: ¿ Algún impedimento?
B9: Yman Gonzales | C9: Primera entrega funcionando en un plazo de 2 semanas (4/07-13/07). De la Solución Web para un Sistema de gestion en Tiempo Real del negocio YUPI SAC | D9: Validar el Modelo de base de datos | E9: Pruebas del Registro de Usuarios | F9: Problemas de conexión a base de datos
B14: Rodriguez Quispe | D14: Validar el Registro_Clientes | E14: Pruebas del Registro_Clientes | F14: Problemas de conexión a base de datos
B19: Cachay Santa Cruz | D19: Validar el Registro_Productos | E19: Pruebas de la funcionalidad del Carrito_Compras | F19: Errores de Código
B24: Morales Zeballos | D24: Validar la Generacion del Reportes_Ventas | E24: Pruebas del Registro_Proveedores | F24: Ningún error

Sheet 2.2 Evento Daily Scrum
B2: EVENTOS SCRUM: SPRINT 1 | D2: Nombre del Negocio | E2: Karcher Perú SAC | F2: Fecha:08/07/2022
D3: Participantes | E3: 1 Yman Gonzales
E4: 2 Rodriguez Quispe
E5: 3 Cachay Santa Cruz
B7: 2.0 EVENTO DAILY SCRUM
B8: SCRUM TEAM | C8: Meta | D8: ¿ Que hiciste ayer? | E8: ¿ Qué vas a hacer hoy? | F8: ¿ Algún impedimento?
B9: Yman Gonzales | C9: Primera entrega funcionando en un plazo de 3 semanas (14 de Julio). De la Solución Web para un Sistemas Integrado de Ventas, Compras y Almacén
B14: Rodriguez Quispe
B19: Cachay Santa Cruz
B24: Morales Zeballos

Sheet Scrum Board
C2: SCRUM BOARD SPRINT 1
C4: PLANNING | D4: DOING | E4: IN REVIEW | F4: IN TESTING | G4: DONE
C5: PB01 | G5: PB01
C6: PB02 | G6: PB02
C7: PB03 | G7: PB03
C8: PB04 | G8: PB04
C9: PB05 | G9: PB05
C10: PB06 | G10: PB06
C11: PB07 | G11: PB07
C12: PB24 | G12: PB24
C13: PB25 | G13: PB25
C14: PB26 | G14: PB26

Sheet 3.0 Sprint Review
B2: EVENTOS SCRUM: SPRINT REVIEW | D2: Nombre del Negocio | E2: Yupi SAC | F2: Fecha:13/07/2026 | G2: SCRUM MASTER
D3: Participantes | E3: 1 Eder Makino Perze | G3: PRODUCT OWNER
G4: DEVELOPERS SCRUM
G5: CLIENTE
G6: OTROS STAKEHOLDERS TI
B8: 3.0 EVENTO SPRINT REVIEW: DEMOSTRACIÓN EN TIEMPO REAL DEL PRIMER ENTREGABLE FUNCIONANDO
B9: Nro. Sprint | C9: Meta 100% | D9: Fecha de Inicio | E9: Fecha Final | F9: Duración | G9: Estado | H9: Impedimentos | I9: Feedback
B10: Sprint 1 | C10: Primera entrega funcionando en un plazo de 2 semanas (4/07-13/07). De la Solución Web para un Sistema de gestion en Tiempo Real del negocio YUPI SAC PB01, PB02, PB03, PB04, PB05, PB06, PB07, PB24, PB25, PB26 | D10: 46207 | E10: 46581 | F10: 10 dias | G10: TERMINADO 100% | H10: - Falta de comunicación entre los integrar antes del proyecto - Falta de experiencia para trabajar con base de datos y Java web JSP - Falta de conocimientos para utilizar los frameworks Bootstrap, React Falta de comunicación, transparencia Dificultadas de programación web para generar responsividad Errores para programar integracion de backend | I10: Mejorar el ritmo de trabajo para cumplir con las entregas tempranas Ante la ocurrencia de un incidente por parte de los developers comunicar inmediantamente al Scrum Master para solucionar el impedimento

Sheet 4.0 Sprint Rertrospective
B2: EVENTOS SCRUM: SPRINT RESTROSPECTIVE | D2: Nombre del Negocio | E2: Karcher Perú SAC | F2: Fecha:21/11/2022 | G2: SCRUM MASTER
D3: Participantes | E3: 1 Yman Gonzales | G3: DEVELOPERS SCRUM
E4: 2 Rodriguez Quispe
E5: 3 Cachay Santa Cruz
B8: 4.0 EVENTO SPRINT RETROSPECTIVE
B9: Nro. Sprint | C9: Meta 100% | D9: ¿Qué salió bien en la iteración del Sprint 1? (aciertos) | F9: ¿Qué no salió bien en la iteración del Sprint 1? (errores, BUG) | H9: ¿Qué mejoras debemos implementar en el próximo Sprint 2 para ser más ágiles? (recomendaciones de mejora continua)
B10: Sprint 1 | C10: Primera entrega funcionando en un plazo de 2 semanas (4/07-13/07). De la Solución Web para un Sistema de gestion en Tiempo Real del negocio YUPI SAC PB01, PB02, PB03, PB04, PB05, PB06, PB07, PB24, PB25, PB26 | D10: La programacion de la Interfaz FrontEnd con diseño intuitivo | F10: La programacion de la Seguridad JWT | H10: - Practicar e investigar la programacion para la seguridad y autenticacion de usuarios
D16: Programacion de entidades con las dependencias adecuadas | F16: Programacion para la logica de negocio del Backend | H16: {=- Integrar Apis en FrontEnd y la conexión a la base de datos para datos persistentes} -> #NAME?

Sheet Burn Down Charts
B8: DIAS | C8: IDEAL | E8: Puntos Reales
B9: 1 | C9: 520 | E9: 520
B10: 2 | C10: =C9-52 -> 468 | E10: 450
B11: 3 | C11: =C10-52 -> 416 | E11: 400
B12: 4 | C12: =C11-52 -> 364 | E12: 360
B13: 5 | C13: =C12-52 -> 312 | E13: 350
B14: 6 | C14: =C13-52 -> 260 | E14: 250
B15: 7 | C15: =C14-52 -> 208 | E15: 160
B16: 8 | C16: =C15-52 -> 156 | E16: 150
B17: 9 | C17: =C16-52 -> 104 | E17: 120
B18: 10 | C18: =C17-52 -> 52 | E18: 55
B19: 11 | C19: =C18-52 -> 0 | E19: 0
C20: 520
B23: Ideal | C23: 52 Puntos por dia
B24: Total de puntos en Sprint 1 | E24: 520 puntos
B25: Ideal = Total de Puntos de Historias de Usuario / Total de dias del Sprint
B26: Ideal | D26: 52

Sheet Sprint Planning Sprint 2
A2: SPRINT PLANNING: SPRINT 2: SOLUCIÓN WEB
B4: SPRINT 1 | C4: SPRINT 2 | D4: SPRINT 3
C5: PB01
C6: PB02
C7: PB08
C8: PB12
C9: PB13
C10: PB14
C11: PB16
C12: PB17
C13: PB18
C14: PB19

Sheet Evento 2 Daily Scrum 01
B2: EVENTOS SCRUM: SPRINT 2 | D2: Nombre del Negocio | E2: Karcher Perú SAC | F2: Fecha:26/07/2022
D3: Participantes | E3: 1 Yman Gonzales
E4: 2 Rodriguez Quispe
E5: 3 Cachay Santa Cruz
B7: 2.0 EVENTO DAILY SCRUM
B8: SCRUM TEAM | C8: Meta | D8: ¿ Que hiciste ayer? | E8: ¿ Qué vas a hacer hoy? | F8: ¿ Algún impedimento?
B9: Yman Gonzales | C9: Segunda entrega funcionando al 100% en un plazo de 3 semanas 5 de Agosto. De la Solución Web para un Sistemas Integrado de Ventas, Compras y Almacén. PB01, PB02, PB08, PB12, PB13, PB14, PB16, PB17, PB18, PB19
B14: Rodriguez Quispe
B19: Cachay Santa Cruz
B24: Morales Zeballos

Sheet Evento 2 Daily Scrum 02
B2: EVENTOS SCRUM: SPRINT 2 | D2: Nombre del Negocio | E2: Karcher Perú SAC | F2: Fecha:01/08/2022
D3: Participantes | E3: 1 Yman Gonzales
E4: 2 Rodriguez Quispe
E5: 3 Cachay Santa Cruz
B7: 2.0 EVENTO DAILY SCRUM
B8: SCRUM TEAM | C8: Meta | D8: ¿ Que hiciste ayer? | E8: ¿ Qué vas a hacer hoy? | F8: ¿ Algún impedimento?
B9: Yman Gonzales | C9: Segunda entrega funcionando al 100% en un plazo de 3 semanas 5 de Agosto. De la Solución Web para un Sistemas Integrado de Ventas, Compras y Almacén. PB01, PB02, PB08, PB12, PB13, PB14, PB16, PB17, PB18, PB19
B14: Rodriguez Quispe
B19: Cachay Santa Cruz
B24: Morales Zeballos

Sheet Evento 3 Daily Scrum 03
B2: EVENTOS SCRUM: SPRINT 2 | D2: Nombre del Negocio | E2: Karcher Perú SAC | F2: Fecha:02/08/2022
D3: Participantes | E3: 1 Yman Gonzales
E4: 2 Rodriguez Quispe
E5: 3 Cachay Santa Cruz
B7: 2.0 EVENTO DAILY SCRUM
B8: SCRUM TEAM | C8: Meta | D8: ¿ Que hiciste ayer? | E8: ¿ Qué vas a hacer hoy? | F8: ¿ Algún impedimento?
B9: Yman Gonzales | C9: Segunda entrega funcionando al 100% en un plazo de 3 semanas 5 de Agosto. De la Solución Web para un Sistemas Integrado de Ventas, Compras y Almacén. PB01, PB02, PB08, PB12, PB13, PB14, PB16, PB17, PB18, PB19
B14: Rodriguez Quispe
B19: Cachay Santa Cruz
B24: Morales Zeballos

Sheet Evento 4 Daily Scrum 04
B2: EVENTOS SCRUM: SPRINT 2 | D2: Nombre del Negocio | E2: Karcher Perú SAC | F2: Fecha:04/08/2022
D3: Participantes | E3: 1 Yman Gonzales
E4: 2 Rodriguez Quispe
E5: 3 Cachay Santa Cruz
B7: 2.0 EVENTO DAILY SCRUM
B8: SCRUM TEAM | C8: Meta | D8: ¿ Que hiciste ayer? | E8: ¿ Qué vas a hacer hoy? | F8: ¿ Algún impedimento?
B9: Yman Gonzales | C9: Segunda entrega funcionando al 100% en un plazo de 3 semanas 5 de Agosto. De la Solución Web para un Sistemas Integrado de Ventas, Compras y Almacén. PB01, PB02, PB08, PB12, PB13, PB14, PB16, PB17, PB18, PB19
B14: Rodriguez Quispe
B19: Cachay Santa Cruz
B24: Morales Zeballos

Sheet Scrum Board Sprint 2
C2: SCRUM BOARD SPRINT 2
C4: PLANNING | D4: DOING | E4: IN REVIEW | F4: IN TESTING | G4: DONE
C5: PB01
C6: PB02
C7: PB08
C8: PB12
C9: PB13
C10: PB14
C11: PB16
C12: PB17
C13: PB18
C14: PB19
